import pytest
from django.core.exceptions import ValidationError

@pytest.mark.django_db
def test_dealer_valid_vat(test_dealer_instance_valid_vat):
    """
    Given a dealer instance with a valid VAT number,
    When the instance is validated,
    Then no ValidationError should be raised.
    """
    # The full_clean() method validates the dealer instance against model constraints
    try:
        test_dealer_instance_valid_vat.full_clean()
    except ValidationError:
        pytest.fail("ValidationError raised for a valid VAT number unexpectedly.")

@pytest.mark.django_db
def test_dealer_invalid_vat(test_dealer_instance_invalid_vat):
    """
    Given a dealer instance with an invalid VAT number,
    When the instance is validated,
    Then a ValidationError should be raised.
    """
    # We expect a ValidationError to be raised due to the invalid VAT number.
    with pytest.raises(ValidationError):
        test_dealer_instance_invalid_vat.full_clean()